<?xml version="1.0" encoding="UTF-8"?>
<testng-results ignored="0" total="3" passed="0" failed="3" skipped="0">
  <reporter-output>
  </reporter-output>
  <suite started-at="2022-03-27T17:40:35 EET" name="Default suite" finished-at="2022-03-27T17:41:17 EET" duration-ms="41682">
    <groups>
    </groups>
    <test started-at="2022-03-27T17:40:35 EET" name="Default test" finished-at="2022-03-27T17:41:17 EET" duration-ms="41682">
      <class name="frist_selenium.Invalid_Login">
        <test-method is-config="true" signature="FristSteps()[pri:0, instance:frist_selenium.Invalid_Login@4f209819]" started-at="2022-03-27T17:40:35 EET" name="FristSteps" finished-at="2022-03-27T17:40:42 EET" duration-ms="6078" status="PASS">
          <reporter-output>
          </reporter-output>
        </test-method> <!-- FristSteps -->
        <test-method signature="InvalidName()[pri:1, instance:frist_selenium.Invalid_Login@4f209819]" started-at="2022-03-27T17:40:42 EET" name="InvalidName" finished-at="2022-03-27T17:40:50 EET" duration-ms="8197" status="FAIL">
          <exception class="java.lang.AssertionError">
            <message>
              <![CDATA[expected [https://www.saucedemo.com/inventory.html] but found [https://www.saucedemo.com/]]]>
            </message>
            <full-stacktrace>
              <![CDATA[java.lang.AssertionError: expected [https://www.saucedemo.com/inventory.html] but found [https://www.saucedemo.com/]
at org.testng.Assert.fail(Assert.java:99)
at org.testng.Assert.failNotEquals(Assert.java:1037)
at org.testng.Assert.assertEqualsImpl(Assert.java:140)
at org.testng.Assert.assertEquals(Assert.java:122)
at org.testng.Assert.assertEquals(Assert.java:629)
at org.testng.Assert.assertEquals(Assert.java:639)
at frist_selenium.Invalid_Login.InvalidName(Invalid_Login.java:58)
at java.base/jdk.internal.reflect.NativeMethodAccessorImpl.invoke0(Native Method)
at java.base/jdk.internal.reflect.NativeMethodAccessorImpl.invoke(NativeMethodAccessorImpl.java:78)
at java.base/jdk.internal.reflect.DelegatingMethodAccessorImpl.invoke(DelegatingMethodAccessorImpl.java:43)
at java.base/java.lang.reflect.Method.invoke(Method.java:567)
at org.testng.internal.MethodInvocationHelper.invokeMethod(MethodInvocationHelper.java:133)
at org.testng.internal.TestInvoker.invokeMethod(TestInvoker.java:598)
at org.testng.internal.TestInvoker.invokeTestMethod(TestInvoker.java:173)
at org.testng.internal.MethodRunner.runInSequence(MethodRunner.java:46)
at org.testng.internal.TestInvoker$MethodInvocationAgent.invoke(TestInvoker.java:824)
at org.testng.internal.TestInvoker.invokeTestMethods(TestInvoker.java:146)
at org.testng.internal.TestMethodWorker.invokeTestMethods(TestMethodWorker.java:146)
at org.testng.internal.TestMethodWorker.run(TestMethodWorker.java:128)
at java.base/java.util.ArrayList.forEach(ArrayList.java:1511)
at org.testng.TestRunner.privateRun(TestRunner.java:794)
at org.testng.TestRunner.run(TestRunner.java:596)
at org.testng.SuiteRunner.runTest(SuiteRunner.java:377)
at org.testng.SuiteRunner.runSequentially(SuiteRunner.java:371)
at org.testng.SuiteRunner.privateRun(SuiteRunner.java:332)
at org.testng.SuiteRunner.run(SuiteRunner.java:276)
at org.testng.SuiteRunnerWorker.runSuite(SuiteRunnerWorker.java:53)
at org.testng.SuiteRunnerWorker.run(SuiteRunnerWorker.java:96)
at org.testng.TestNG.runSuitesSequentially(TestNG.java:1212)
at org.testng.TestNG.runSuitesLocally(TestNG.java:1134)
at org.testng.TestNG.runSuites(TestNG.java:1063)
at org.testng.TestNG.run(TestNG.java:1031)
at org.testng.remote.AbstractRemoteTestNG.run(AbstractRemoteTestNG.java:115)
at org.testng.remote.RemoteTestNG.initAndRun(RemoteTestNG.java:251)
at org.testng.remote.RemoteTestNG.main(RemoteTestNG.java:77)
]]>
            </full-stacktrace>
          </exception> <!-- java.lang.AssertionError -->
          <reporter-output>
          </reporter-output>
        </test-method> <!-- InvalidName -->
        <test-method is-config="true" signature="LastStep()[pri:0, instance:frist_selenium.Invalid_Login@4f209819]" started-at="2022-03-27T17:40:50 EET" name="LastStep" finished-at="2022-03-27T17:40:50 EET" duration-ms="181" status="PASS">
          <reporter-output>
          </reporter-output>
        </test-method> <!-- LastStep -->
        <test-method is-config="true" signature="FristSteps()[pri:0, instance:frist_selenium.Invalid_Login@4f209819]" started-at="2022-03-27T17:40:50 EET" name="FristSteps" finished-at="2022-03-27T17:40:55 EET" duration-ms="5245" status="PASS">
          <reporter-output>
          </reporter-output>
        </test-method> <!-- FristSteps -->
        <test-method signature="Invalidpass()[pri:2, instance:frist_selenium.Invalid_Login@4f209819]" started-at="2022-03-27T17:40:55 EET" name="Invalidpass" finished-at="2022-03-27T17:41:03 EET" duration-ms="8184" status="FAIL">
          <exception class="java.lang.AssertionError">
            <message>
              <![CDATA[expected [https://www.saucedemo.com/inventory.html] but found [https://www.saucedemo.com/]]]>
            </message>
            <full-stacktrace>
              <![CDATA[java.lang.AssertionError: expected [https://www.saucedemo.com/inventory.html] but found [https://www.saucedemo.com/]
at org.testng.Assert.fail(Assert.java:99)
at org.testng.Assert.failNotEquals(Assert.java:1037)
at org.testng.Assert.assertEqualsImpl(Assert.java:140)
at org.testng.Assert.assertEquals(Assert.java:122)
at org.testng.Assert.assertEquals(Assert.java:629)
at org.testng.Assert.assertEquals(Assert.java:639)
at frist_selenium.Invalid_Login.Invalidpass(Invalid_Login.java:85)
at java.base/jdk.internal.reflect.NativeMethodAccessorImpl.invoke0(Native Method)
at java.base/jdk.internal.reflect.NativeMethodAccessorImpl.invoke(NativeMethodAccessorImpl.java:78)
at java.base/jdk.internal.reflect.DelegatingMethodAccessorImpl.invoke(DelegatingMethodAccessorImpl.java:43)
at java.base/java.lang.reflect.Method.invoke(Method.java:567)
at org.testng.internal.MethodInvocationHelper.invokeMethod(MethodInvocationHelper.java:133)
at org.testng.internal.TestInvoker.invokeMethod(TestInvoker.java:598)
at org.testng.internal.TestInvoker.invokeTestMethod(TestInvoker.java:173)
at org.testng.internal.MethodRunner.runInSequence(MethodRunner.java:46)
at org.testng.internal.TestInvoker$MethodInvocationAgent.invoke(TestInvoker.java:824)
at org.testng.internal.TestInvoker.invokeTestMethods(TestInvoker.java:146)
at org.testng.internal.TestMethodWorker.invokeTestMethods(TestMethodWorker.java:146)
at org.testng.internal.TestMethodWorker.run(TestMethodWorker.java:128)
at java.base/java.util.ArrayList.forEach(ArrayList.java:1511)
at org.testng.TestRunner.privateRun(TestRunner.java:794)
at org.testng.TestRunner.run(TestRunner.java:596)
at org.testng.SuiteRunner.runTest(SuiteRunner.java:377)
at org.testng.SuiteRunner.runSequentially(SuiteRunner.java:371)
at org.testng.SuiteRunner.privateRun(SuiteRunner.java:332)
at org.testng.SuiteRunner.run(SuiteRunner.java:276)
at org.testng.SuiteRunnerWorker.runSuite(SuiteRunnerWorker.java:53)
at org.testng.SuiteRunnerWorker.run(SuiteRunnerWorker.java:96)
at org.testng.TestNG.runSuitesSequentially(TestNG.java:1212)
at org.testng.TestNG.runSuitesLocally(TestNG.java:1134)
at org.testng.TestNG.runSuites(TestNG.java:1063)
at org.testng.TestNG.run(TestNG.java:1031)
at org.testng.remote.AbstractRemoteTestNG.run(AbstractRemoteTestNG.java:115)
at org.testng.remote.RemoteTestNG.initAndRun(RemoteTestNG.java:251)
at org.testng.remote.RemoteTestNG.main(RemoteTestNG.java:77)
]]>
            </full-stacktrace>
          </exception> <!-- java.lang.AssertionError -->
          <reporter-output>
          </reporter-output>
        </test-method> <!-- Invalidpass -->
        <test-method is-config="true" signature="LastStep()[pri:0, instance:frist_selenium.Invalid_Login@4f209819]" started-at="2022-03-27T17:41:03 EET" name="LastStep" finished-at="2022-03-27T17:41:04 EET" duration-ms="182" status="PASS">
          <reporter-output>
          </reporter-output>
        </test-method> <!-- LastStep -->
        <test-method is-config="true" signature="FristSteps()[pri:0, instance:frist_selenium.Invalid_Login@4f209819]" started-at="2022-03-27T17:41:04 EET" name="FristSteps" finished-at="2022-03-27T17:41:09 EET" duration-ms="5223" status="PASS">
          <reporter-output>
          </reporter-output>
        </test-method> <!-- FristSteps -->
        <test-method signature="Invalidpass_and_username()[pri:2, instance:frist_selenium.Invalid_Login@4f209819]" started-at="2022-03-27T17:41:09 EET" name="Invalidpass_and_username" finished-at="2022-03-27T17:41:17 EET" duration-ms="8173" status="FAIL">
          <exception class="java.lang.AssertionError">
            <message>
              <![CDATA[expected [https://www.saucedemo.com/inventory.html] but found [https://www.saucedemo.com/]]]>
            </message>
            <full-stacktrace>
              <![CDATA[java.lang.AssertionError: expected [https://www.saucedemo.com/inventory.html] but found [https://www.saucedemo.com/]
at org.testng.Assert.fail(Assert.java:99)
at org.testng.Assert.failNotEquals(Assert.java:1037)
at org.testng.Assert.assertEqualsImpl(Assert.java:140)
at org.testng.Assert.assertEquals(Assert.java:122)
at org.testng.Assert.assertEquals(Assert.java:629)
at org.testng.Assert.assertEquals(Assert.java:639)
at frist_selenium.Invalid_Login.Invalidpass_and_username(Invalid_Login.java:113)
at java.base/jdk.internal.reflect.NativeMethodAccessorImpl.invoke0(Native Method)
at java.base/jdk.internal.reflect.NativeMethodAccessorImpl.invoke(NativeMethodAccessorImpl.java:78)
at java.base/jdk.internal.reflect.DelegatingMethodAccessorImpl.invoke(DelegatingMethodAccessorImpl.java:43)
at java.base/java.lang.reflect.Method.invoke(Method.java:567)
at org.testng.internal.MethodInvocationHelper.invokeMethod(MethodInvocationHelper.java:133)
at org.testng.internal.TestInvoker.invokeMethod(TestInvoker.java:598)
at org.testng.internal.TestInvoker.invokeTestMethod(TestInvoker.java:173)
at org.testng.internal.MethodRunner.runInSequence(MethodRunner.java:46)
at org.testng.internal.TestInvoker$MethodInvocationAgent.invoke(TestInvoker.java:824)
at org.testng.internal.TestInvoker.invokeTestMethods(TestInvoker.java:146)
at org.testng.internal.TestMethodWorker.invokeTestMethods(TestMethodWorker.java:146)
at org.testng.internal.TestMethodWorker.run(TestMethodWorker.java:128)
at java.base/java.util.ArrayList.forEach(ArrayList.java:1511)
at org.testng.TestRunner.privateRun(TestRunner.java:794)
at org.testng.TestRunner.run(TestRunner.java:596)
at org.testng.SuiteRunner.runTest(SuiteRunner.java:377)
at org.testng.SuiteRunner.runSequentially(SuiteRunner.java:371)
at org.testng.SuiteRunner.privateRun(SuiteRunner.java:332)
at org.testng.SuiteRunner.run(SuiteRunner.java:276)
at org.testng.SuiteRunnerWorker.runSuite(SuiteRunnerWorker.java:53)
at org.testng.SuiteRunnerWorker.run(SuiteRunnerWorker.java:96)
at org.testng.TestNG.runSuitesSequentially(TestNG.java:1212)
at org.testng.TestNG.runSuitesLocally(TestNG.java:1134)
at org.testng.TestNG.runSuites(TestNG.java:1063)
at org.testng.TestNG.run(TestNG.java:1031)
at org.testng.remote.AbstractRemoteTestNG.run(AbstractRemoteTestNG.java:115)
at org.testng.remote.RemoteTestNG.initAndRun(RemoteTestNG.java:251)
at org.testng.remote.RemoteTestNG.main(RemoteTestNG.java:77)
]]>
            </full-stacktrace>
          </exception> <!-- java.lang.AssertionError -->
          <reporter-output>
          </reporter-output>
        </test-method> <!-- Invalidpass_and_username -->
        <test-method is-config="true" signature="LastStep()[pri:0, instance:frist_selenium.Invalid_Login@4f209819]" started-at="2022-03-27T17:41:17 EET" name="LastStep" finished-at="2022-03-27T17:41:17 EET" duration-ms="179" status="PASS">
          <reporter-output>
          </reporter-output>
        </test-method> <!-- LastStep -->
      </class> <!-- frist_selenium.Invalid_Login -->
    </test> <!-- Default test -->
  </suite> <!-- Default suite -->
</testng-results>
